[2024-09-03T11:18:49.835+0000] {taskinstance.py:1103} INFO - Dependencies all met for dep_context=non-requeueable deps ti=<TaskInstance: 1__ingestion.transform scheduled__2024-08-30T22:40:00+00:00 [queued]>
[2024-09-03T11:18:49.841+0000] {taskinstance.py:1103} INFO - Dependencies all met for dep_context=requeueable deps ti=<TaskInstance: 1__ingestion.transform scheduled__2024-08-30T22:40:00+00:00 [queued]>
[2024-09-03T11:18:49.841+0000] {taskinstance.py:1308} INFO - Starting attempt 1 of 1
[2024-09-03T11:18:49.864+0000] {taskinstance.py:1327} INFO - Executing <Task(PythonOperator): transform> on 2024-08-30 22:40:00+00:00
[2024-09-03T11:18:49.868+0000] {standard_task_runner.py:57} INFO - Started process 12753 to run task
[2024-09-03T11:18:49.871+0000] {standard_task_runner.py:84} INFO - Running: ['airflow', 'tasks', 'run', '1__ingestion', 'transform', 'scheduled__2024-08-30T22:40:00+00:00', '--job-id', '515', '--raw', '--subdir', 'DAGS_FOLDER/ingestion.py', '--cfg-path', '/tmp/tmptpy2_g0u']
[2024-09-03T11:18:49.872+0000] {standard_task_runner.py:85} INFO - Job 515: Subtask transform
[2024-09-03T11:18:49.912+0000] {task_command.py:410} INFO - Running <TaskInstance: 1__ingestion.transform scheduled__2024-08-30T22:40:00+00:00 [running]> on host airflow.p5gcuddgvhqutph3bove52popc.rx.internal.cloudapp.net
[2024-09-03T11:18:49.988+0000] {taskinstance.py:1545} INFO - Exporting env vars: AIRFLOW_CTX_DAG_OWNER='airflow' AIRFLOW_CTX_DAG_ID='1__ingestion' AIRFLOW_CTX_TASK_ID='transform' AIRFLOW_CTX_EXECUTION_DATE='2024-08-30T22:40:00+00:00' AIRFLOW_CTX_TRY_NUMBER='1' AIRFLOW_CTX_DAG_RUN_ID='scheduled__2024-08-30T22:40:00+00:00'
[2024-09-03T11:18:49.989+0000] {taskinstance.py:1824} ERROR - Task failed with exception
Traceback (most recent call last):
  File "/home/airflow-vm/data-engineer-batch-processing-financial-services/.venv/lib/python3.10/site-packages/airflow/operators/python.py", line 181, in execute
    return_value = self.execute_callable()
  File "/home/airflow-vm/data-engineer-batch-processing-financial-services/.venv/lib/python3.10/site-packages/airflow/operators/python.py", line 198, in execute_callable
    return self.python_callable(*self.op_args, **self.op_kwargs)
TypeError: transform() missing 1 required positional argument: 'res'
[2024-09-03T11:18:49.993+0000] {taskinstance.py:1345} INFO - Marking task as FAILED. dag_id=1__ingestion, task_id=transform, execution_date=20240830T224000, start_date=20240903T111849, end_date=20240903T111849
[2024-09-03T11:18:50.012+0000] {standard_task_runner.py:104} ERROR - Failed to execute job 515 for task transform (transform() missing 1 required positional argument: 'res'; 12753)
[2024-09-03T11:18:50.043+0000] {local_task_job_runner.py:225} INFO - Task exited with return code 1
[2024-09-03T11:18:50.061+0000] {taskinstance.py:2651} INFO - 0 downstream tasks scheduled from follow-on schedule check
