[2024-09-03T11:17:20.478+0000] {taskinstance.py:1103} INFO - Dependencies all met for dep_context=non-requeueable deps ti=<TaskInstance: 1__ingestion.transform scheduled__2024-08-30T20:40:00+00:00 [queued]>
[2024-09-03T11:17:20.484+0000] {taskinstance.py:1103} INFO - Dependencies all met for dep_context=requeueable deps ti=<TaskInstance: 1__ingestion.transform scheduled__2024-08-30T20:40:00+00:00 [queued]>
[2024-09-03T11:17:20.484+0000] {taskinstance.py:1308} INFO - Starting attempt 1 of 1
[2024-09-03T11:17:20.508+0000] {taskinstance.py:1327} INFO - Executing <Task(PythonOperator): transform> on 2024-08-30 20:40:00+00:00
[2024-09-03T11:17:20.512+0000] {standard_task_runner.py:57} INFO - Started process 11878 to run task
[2024-09-03T11:17:20.515+0000] {standard_task_runner.py:84} INFO - Running: ['airflow', 'tasks', 'run', '1__ingestion', 'transform', 'scheduled__2024-08-30T20:40:00+00:00', '--job-id', '491', '--raw', '--subdir', 'DAGS_FOLDER/ingestion.py', '--cfg-path', '/tmp/tmpbul5ex55']
[2024-09-03T11:17:20.517+0000] {standard_task_runner.py:85} INFO - Job 491: Subtask transform
[2024-09-03T11:17:20.560+0000] {task_command.py:410} INFO - Running <TaskInstance: 1__ingestion.transform scheduled__2024-08-30T20:40:00+00:00 [running]> on host airflow.p5gcuddgvhqutph3bove52popc.rx.internal.cloudapp.net
[2024-09-03T11:17:20.637+0000] {taskinstance.py:1545} INFO - Exporting env vars: AIRFLOW_CTX_DAG_OWNER='airflow' AIRFLOW_CTX_DAG_ID='1__ingestion' AIRFLOW_CTX_TASK_ID='transform' AIRFLOW_CTX_EXECUTION_DATE='2024-08-30T20:40:00+00:00' AIRFLOW_CTX_TRY_NUMBER='1' AIRFLOW_CTX_DAG_RUN_ID='scheduled__2024-08-30T20:40:00+00:00'
[2024-09-03T11:17:20.639+0000] {taskinstance.py:1824} ERROR - Task failed with exception
Traceback (most recent call last):
  File "/home/airflow-vm/data-engineer-batch-processing-financial-services/.venv/lib/python3.10/site-packages/airflow/operators/python.py", line 181, in execute
    return_value = self.execute_callable()
  File "/home/airflow-vm/data-engineer-batch-processing-financial-services/.venv/lib/python3.10/site-packages/airflow/operators/python.py", line 198, in execute_callable
    return self.python_callable(*self.op_args, **self.op_kwargs)
TypeError: transform() missing 1 required positional argument: 'res'
[2024-09-03T11:17:20.642+0000] {taskinstance.py:1345} INFO - Marking task as FAILED. dag_id=1__ingestion, task_id=transform, execution_date=20240830T204000, start_date=20240903T111720, end_date=20240903T111720
[2024-09-03T11:17:20.662+0000] {standard_task_runner.py:104} ERROR - Failed to execute job 491 for task transform (transform() missing 1 required positional argument: 'res'; 11878)
[2024-09-03T11:17:20.687+0000] {local_task_job_runner.py:225} INFO - Task exited with return code 1
[2024-09-03T11:17:20.706+0000] {taskinstance.py:2651} INFO - 0 downstream tasks scheduled from follow-on schedule check
